<?xml version="1.0" encoding="utf-8"?>
<mujoco model="door_knob">
	<compiler angle="radian"/>
	<include file="../../robot/blue_floatinghook.xml"/>
	<option gravity="0 0 0" timestep="0.001"/>
	<visual>
		<map fogend="5" fogstart="3" force="0.1" zfar="10" znear="0.01"/>
		<quality shadowsize="2048"/>
		<global offheight="256" offwidth="256"/>
	</visual>
	<asset>
		<mesh file="../../door/leverknobs/1551849078/body_1.stl" name="door_knob_1" scale="0.0015 0.0015 0.0015"/>
		<mesh file="../../door/leverknobs/1551849078/body_2.stl" name="door_knob_2" scale="0.0015 0.0015 0.0015"/>
		<mesh file="../../door/leverknobs/1551849078/body_3.stl" name="door_knob_3" scale="0.0015 0.0015 0.0015"/>
		<mesh file="../../door/leverknobs/1551849078/body_4.stl" name="door_knob_4" scale="0.0015 0.0015 0.0015"/>
		<mesh file="../../door/leverknobs/1551849078/body_5.stl" name="door_knob_5" scale="0.0015 0.0015 0.0015"/>
		<texture builtin="flat" height="32" name="wall_geom" type="2d" width="32"/>
		<texture builtin="flat" height="32" name="frame_geom" type="2d" width="32"/>
		<texture builtin="flat" height="32" name="door_geom" type="2d" width="32"/>
		<texture builtin="flat" height="32" name="knob_geom" type="2d" width="32"/>
		<texture builtin="gradient" height="128" rgb1="0.4 0.6 0.8" rgb2="0 0 0" type="skybox" width="128"/>
		<texture builtin="gradient" height="512" name="texplane" rgb1="0.24 0.48 0.07" rgb2="0.15 0.42 0.19" type="2d" width="512"/>
		<material name="Paint" shininess="0.35" specular="0.39" texture="wall_geom"/>
		<material name="Wood" shininess="0.11" specular="0.06" texture="frame_geom"/>
		<material name="Carpet" shininess="0.02" specular="0.02" texture="door_geom"/>
		<material name="Metal" shininess="0.92" specular="0.99" texture="knob_geom"/>
		<material name="Floor" texture="texplane"/>
	</asset>
	<contact>
		<pair geom1="knob_latch" geom2="door_frame_0" solref="0.01 1"/>
		<pair geom1="knob_latch" geom2="door_frame_1" solref="0.01 1"/>
		<pair geom1="knob_latch" geom2="door_frame_2" solref="0.01 1"/>
		<pair geom1="knob_latch" geom2="door_frame_3" solref="0.01 1"/>
	</contact>
	<default>
		<joint armature="1" damping="1" limited="true"/>
		<default class="wall">
			<geom rgba="0.26 0.6 0.08 1.0" type="mesh"/>
		</default>
		<default class="frame">
			<geom rgba="0.77 0.83 0.7 1.0" type="mesh"/>
		</default>
		<default class="door">
			<geom rgba="0.33 0.29 0.77 1.0" type="mesh"/>
		</default>
		<default class="door_knob">
			<geom condim="4" rgba="0.28 0.26 0.68 1.0" type="mesh"/>
		</default>
		<default class="robot">
			<joint damping="0.09"/>
		</default>
	</default>
	<worldbody>
		<light diffuse="0.9 0.9 1.0" dir="-0.25 -0.41 -0.42" directional="true" pos="4.06 -4.67 6.03"/>
		<light diffuse="1.0 0.9 1.0" dir="-0.22 -0.37 -0.43" directional="true" pos="4.64 -4.35 4.45"/>
		<geom material="Floor" name="floor" pos="0 0 -0.05" size="15.0 15.0 0.05" type="plane"/>
		<camera fovy="60" mode="fixed" name="camera1" pos="0.99 0.5 1.0" euler="0.0 1.57 1.57"/>
		<camera fovy="60" mode="fixed" name="camera2" pos="0.5 0.0 1.99" euler="0 0 0"/>
		<body childclass="wall" name="wall_link" pos="0.0 0.0 0.0">
			<inertial mass="100" pos="0 0 0" diaginertia="0.0001 0.0001 0.0001"/>
			<geom material="Paint" name="wall_0" pos="-0.15 -1.57 1.18" size="0.15 1.0 1.18" type="box" euler="0 0 0"/>
			<geom material="Paint" name="wall_1" pos="-0.15 1.6 1.18" size="0.15 1.0 1.18" type="box" euler="0 0 0"/>
			<geom material="Paint" name="wall_2" pos="-0.15 0 2.86" size="0.15 2.6 0.5" type="box" euler="0 0 0"/>
			<body childclass="frame" name="frame_link" pos="0 -0.35 1">
				<inertial mass="500" pos="0 0 0" diaginertia="0.0001 0.0001 0.0001"/>
				<geom material="Carpet" name="door_frame_0" pos="0 -0.21000000000000002 0.17999999999999994" size="0.01 0.05 1.18" type="box" euler="0 0 0"/>
				<geom material="Carpet" name="door_frame_1" pos="0 0.91 0.17999999999999994" size="0.01 0.05 1.18" type="box" euler="0 0 0"/>
				<geom material="Carpet" name="door_frame_2" pos="0 0.35 1.3099999999999998" size="0.01 0.6 0.05" type="box" euler="0 0 0"/>
				<geom material="Carpet" name="door_frame_3" pos="-0.0395 -0.21000000000000002 0.17999999999999994" size="0.01 0.05 1.18" type="box" euler="0 0 0"/>
				<geom material="Carpet" name="door_frame_4" pos="-0.0395 0.91 0.17999999999999994" size="0.01 0.05 1.18" type="box" euler="0 0 0"/>
				<geom material="Carpet" name="door_frame_5" pos="-0.0395 0.35 1.3099999999999998" size="0.01 0.6 0.05" type="box" euler="0 0 0"/>
				<body childclass="door" name="door_link" pos="0 0 0">
					<joint armature="0.0001" axis="0 0 1" damping="1.2" frictionloss="0" limited="true" name="hinge0" pos="0 0.85 0" range="-0.0 1.57" stiffness="0.14" type="hinge"/>
					<geom material="Wood" name="door0" pos="0 0.35 0.1299999999999999" size="0.01 0.5 1.1186999999999998" type="box" euler="0 0 0"/>
					<inertial mass="13.559999999999999" pos="0 0.35 0.1299999999999999" diaginertia="6.901587999999998 5.772039999999998 1.1304519999999998"/>
					<body childclass="door_knob" name="knob_link" pos="0 0 0">
						<inertial mass="1" pos="0 0 0" diaginertia="0.001 0.001 0.001"/>
						<joint armature="0" axis="0 1 0" damping="30000" frictionloss="0" limited="true" name="target0" range="-0.2 0.3" stiffness="0" type="slide"/>
						<joint armature="0" axis="0 0 1" damping="30000" frictionloss="0" limited="true" name="target1" range="-0.5 0.5" stiffness="0" type="slide"/>
						<joint armature="0.0001" axis="1 0 0" damping="1.71" frictionloss="0" limited="true" name="hinge1" pos="0 0 0" range="-1.325777777777778 1.325777777777778" stiffness="1.02" type="hinge"/>
						<body childclass="door_knob" name="leverknob_link" pos="0.01 0 0">
							<geom friction="0.57 0.002 0.004" material="Carpet" mesh="door_knob_1" name="door_knob_1" euler="-1.57 1.57 0"/>
							<geom friction="0.57 0.002 0.004" material="Carpet" mesh="door_knob_2" name="door_knob_2" euler="-1.57 1.57 0"/>
							<geom friction="0.57 0.002 0.004" material="Carpet" mesh="door_knob_3" name="door_knob_3" euler="-1.57 1.57 0"/>
							<geom friction="0.57 0.002 0.004" material="Carpet" mesh="door_knob_4" name="door_knob_4" euler="-1.57 1.57 0"/>
							<geom friction="0.57 0.002 0.004" material="Carpet" mesh="door_knob_5" name="door_knob_5" euler="-1.57 1.57 0"/>
							<geom material="Paint" name="knob_latch" pos="-0.02975 0 0" size="0.0075 0.18333333333333332 0.05" type="box" euler="0 0 0"/>
							<inertial mass="1" pos="-0.051750000000000004 0 0" diaginertia="0.003009259259259259 0.00022708333333333337 0.0028196759259259256"/>
						</body>
					</body>
				</body>
			</body>
		</body>
	</worldbody>
</mujoco>